Workbook

Sheet SYS INFO
B2: Item | C2: Value | D2: Units | E2: Part Number | F2: Notes
B3: Shunt Resistor | C3: 1.6 | D3: Ohm | E3: ERJ-6DQF1R6V
B4: VSEL | C4: 5 | D4: V
B5: VCC | C5: 3.3 | D5: V
B6: LED Resistor | C6: 470 | D6: Ohm | E6: CRCW0603470RFKEC
B7: LED Forward Voltage | C7: 1.79 | D7: V | E7: HSMH-H190 | F7: Measured FV with multimeter
B8: LDO Power Loss Ratio | C8: =(C4-C5)/C5 -> 0.51515152 | F8: Power loss is directly proportional to system power
B9: System Power Ratio | C9: =1/(1+C8) -> 0.66 | F9: How much the system actually uses in relation to LDO ratio
B11: Measured voltages were exactly ideal values.

Sheet Baselines
B2: Current Sense Amplifier (Multimeter) | F2: 3V3 LED (Multimeter) | J2: System Power (CSA)
B3: Test # | C3: Shunt Voltage (mV) | D3: Estimated System Power (mW) | F3: Test # | G3: Shunt Voltage (V) | H3: Estimated LED Power (mW) | J3: Test # | K3: CSA Power (mW) [QSPI SLEEP] | M3: Test # | N3: CSA Power (mW) [QSPI ACTIVE]
B4: 1 | C4: 49 | D4: =(C4/1000)/('SYS INFO'!$C$3)*'SYS INFO'!$C$4*1000 * 'SYS INFO'!$C$9 -> 101.0625 | F4: 1 | G4: 1.517 | H4: =(G4 / 'SYS INFO'!$C$6) * 'SYS INFO'!$C$5 * 1000 -> 10.651277 | J4: 1 | K4: 151 | M4: 1 | N4: 149
B5: 2 | C5: 48.9 | D5: =(C5/1000)/('SYS INFO'!$C$3)*'SYS INFO'!$C$4*1000 * 'SYS INFO'!$C$9 -> 100.85625 | F5: 2 | G5: 1.517 | H5: =(G5 / 'SYS INFO'!$C$6) * 'SYS INFO'!$C$5 * 1000 -> 10.651277 | J5: 2 | K5: 150 | M5: 2 | N5: 152
B6: 3 | C6: 48.7 | D6: =(C6/1000)/('SYS INFO'!$C$3)*'SYS INFO'!$C$4*1000 * 'SYS INFO'!$C$9 -> 100.44375 | F6: 3 | G6: 1.517 | H6: =(G6 / 'SYS INFO'!$C$6) * 'SYS INFO'!$C$5 * 1000 -> 10.651277 | J6: 3 | K6: 150 | M6: 3 | N6: 150
B7: 4 | C7: 48.7 | D7: =(C7/1000)/('SYS INFO'!$C$3)*'SYS INFO'!$C$4*1000 * 'SYS INFO'!$C$9 -> 100.44375 | F7: 4 | G7: 1.517 | H7: =(G7 / 'SYS INFO'!$C$6) * 'SYS INFO'!$C$5 * 1000 -> 10.651277 | J7: 4 | K7: 149 | M7: 4 | N7: 149
B8: 5 | C8: 49 | D8: =(C8/1000)/('SYS INFO'!$C$3)*'SYS INFO'!$C$4*1000 * 'SYS INFO'!$C$9 -> 101.0625 | F8: 5 | G8: 1.518 | H8: =(G8 / 'SYS INFO'!$C$6) * 'SYS INFO'!$C$5 * 1000 -> 10.658298 | J8: 5 | K8: 149 | M8: 5 | N8: 152
J9: 6 | K9: 151 | M9: 6 | N9: 152
C10: Average | D10: =AVERAGE(D4:D8) -> 100.77375 | G10: Average | H10: =AVERAGE(H4:H8) -> 10.652681 | J10: 7 | K10: 151 | M10: 7 | N10: 149
J11: 8 | K11: 150 | M11: 8 | N11: 150
J12: 9 | K12: 152 | M12: 9 | N12: 152
J13: 10 | K13: 152 | M13: 10 | N13: 151
J14: 11 | K14: 152 | M14: 11 | N14: 150
J15: 12 | K15: 153 | M15: 12 | N15: 150
J16: 13 | K16: 150 | M16: 13 | N16: 149
J17: 14 | K17: 149 | M17: 14 | N17: 151
J18: 15 | K18: 149 | M18: 15 | N18: 151
J19: 16 | K19: 151 | M19: 16 | N19: 152
J20: 17 | K20: 153 | M20: 17 | N20: 149
J21: 18 | K21: 151 | M21: 18 | N21: 154
J22: 19 | K22: 151 | M22: 19 | N22: 152
... J28: 25 | K28: 148 | M28: 25 | N28: 149
J30: Average | K30: =AVERAGE(K4:K28) -> 150.48 | M30: Average | N30: =AVERAGE(N4:N28) -> 150.68
J32: Virtually no difference between QSPI in active/sleep mode.
J33: Makes sense as difference between the two is 40uA which is approx 130uW.
J35: Cannot measure power during read/write as it is a blocking function
J36: Can extrapolate from pg. 113 of datasheet
J38: No need to apply system ratio here. The difference is so small that the ratio would not make an impact on the result

Sheet Camera Test
B2: QVGA Image | F2: VGA Image | K2: Image Capture | N2: No Image Capture | Q2: Image Transfer | V2: Power Summary
B3: Time (ms) | C3: System Power (mW) | D3: Factored System Power (mW) | F3: Time (ms) | G3: System Power (mW) | H3: Factored System Power (mW) | L3: Average Power (mW) | O3: Average Power (mW) | R3: Average Power (mW) | W3: Average Power (mW)
B4: 75 | C4: 298 | D4: =C4*'SYS INFO'!$C$9 -> 196.68 | E4: CAMERA ON | F4: 75 | G4: 149 | H4: =G4 * 'SYS INFO'!$C$9 -> 98.34 | I4: CAMERA ON | K4: QVGA | L4: =AVERAGE(D4:D43) -> 149.2425 | N4: QVGA | O4: =AVERAGE(D44:D80) -> 99.267568 | Q4: QVGA | R4: =AVERAGE(C82:C88) -> 158.14286 | V4: System | W4: =AVERAGE(O4:O5) -> 98.018919
B5: 150 | C5: 220 | D5: =C5*'SYS INFO'!$C$9 -> 145.2 | F5: 150 | G5: 217 | H5: =G5 * 'SYS INFO'!$C$9 -> 143.22 | K5: VGA | L5: =AVERAGE(H5:H43) -> 151.39385 | N5: VGA | O5: =AVERAGE(H44:H80) -> 96.77027 | Q5: VGA | R5: =AVERAGE(G81:G114) -> 161.5 | V5: Camera | W5: =AVERAGE(L4:L5)-W4 -> 52.299254
B6: 225 | C6: 220 | D6: =C6*'SYS INFO'!$C$9 -> 145.2 | F6: 225 | G6: 218 | H6: =G6 * 'SYS INFO'!$C$9 -> 143.88 | K6: Difference | L6: =ABS(L4-L5) -> 2.1513462 | N6: Difference | O6: =ABS(O4-O5) -> 2.4972973 | Q6: Difference | R6: =ABS(R4-R5) -> 3.3571429 | V6: USB | W6: =AVERAGE(R4:R5)-W4 -> 61.80251
B7: 300 | C7: 219 | D7: =C7*'SYS INFO'!$C$9 -> 144.54 | F7: 300 | G7: 221 | H7: =G7 * 'SYS INFO'!$C$9 -> 145.86
B8: 375 | C8: 220 | D8: =C8*'SYS INFO'!$C$9 -> 145.2 | F8: 375 | G8: 222 | H8: =G8 * 'SYS INFO'!$C$9 -> 146.52
B9: 450 | C9: 223 | D9: =C9*'SYS INFO'!$C$9 -> 147.18 | F9: 450 | G9: 220 | H9: =G9 * 'SYS INFO'!$C$9 -> 145.2 | N9: No apparent difference in power consumption between VGA and QVGA outside of runtime as power difference within one magnitude of uncertainty
B10: 525 | C10: 222 | D10: =C10*'SYS INFO'!$C$9 -> 146.52 | F10: 525 | G10: 225 | H10: =G10 * 'SYS INFO'!$C$9 -> 148.5
B11: 600 | C11: 223 | D11: =C11*'SYS INFO'!$C$9 -> 147.18 | F11: 600 | G11: 223 | H11: =G11 * 'SYS INFO'!$C$9 -> 147.18
B12: 675 | C12: 222 | D12: =C12*'SYS INFO'!$C$9 -> 146.52 | F12: 675 | G12: 218 | H12: =G12 * 'SYS INFO'!$C$9 -> 143.88
B13: 750 | C13: 227 | D13: =C13*'SYS INFO'!$C$9 -> 149.82 | F13: 750 | G13: 219 | H13: =G13 * 'SYS INFO'!$C$9 -> 144.54
B14: 825 | C14: 223 | D14: =C14*'SYS INFO'!$C$9 -> 147.18 | F14: 825 | G14: 218 | H14: =G14 * 'SYS INFO'!$C$9 -> 143.88
B15: 900 | C15: 223 | D15: =C15*'SYS INFO'!$C$9 -> 147.18 | F15: 900 | G15: 218 | H15: =G15 * 'SYS INFO'!$C$9 -> 143.88
B16: 975 | C16: 223 | D16: =C16*'SYS INFO'!$C$9 -> 147.18 | F16: 975 | G16: 219 | H16: =G16 * 'SYS INFO'!$C$9 -> 144.54
B17: 1050 | C17: 224 | D17: =C17*'SYS INFO'!$C$9 -> 147.84 | F17: 1050 | G17: 219 | H17: =G17 * 'SYS INFO'!$C$9 -> 144.54
B18: 1125 | C18: 222 | D18: =C18*'SYS INFO'!$C$9 -> 146.52 | F18: 1125 | G18: 218 | H18: =G18 * 'SYS INFO'!$C$9 -> 143.88
B19: 1200 | C19: 221 | D19: =C19*'SYS INFO'!$C$9 -> 145.86 | F19: 1200 | G19: 224 | H19: =G19 * 'SYS INFO'!$C$9 -> 147.84
B20: 1275 | C20: 222 | D20: =C20*'SYS INFO'!$C$9 -> 146.52 | F20: 1275 | G20: 223 | H20: =G20 * 'SYS INFO'!$C$9 -> 147.18
B21: 1350 | C21: 221 | D21: =C21*'SYS INFO'!$C$9 -> 145.86 | F21: 1350 | G21: 219 | H21: =G21 * 'SYS INFO'!$C$9 -> 144.54
... B42: 2925 | C42: 222 | D42: =C42*'SYS INFO'!$C$9 -> 146.52 | F42: 2925 | G42: 219 | H42: =G42 * 'SYS INFO'!$C$9 -> 144.54
B43: 3000 | C43: 220 | D43: =C43*'SYS INFO'!$C$9 -> 145.2 | E43: CAMERA OFF | F43: 3000 | G43: 259 | H43: =G43 * 'SYS INFO'!$C$9 -> 170.94 | I43: CAMERA OFF
B44: 3075 | C44: 150 | D44: =C44*'SYS INFO'!$C$9 -> 99 | F44: 3075 | G44: 147 | H44: =G44 * 'SYS INFO'!$C$9 -> 97.02
B45: 3150 | C45: 151 | D45: =C45*'SYS INFO'!$C$9 -> 99.66 | F45: 3150 | G45: 149 | H45: =G45 * 'SYS INFO'!$C$9 -> 98.34
B46: 3225 | C46: 152 | D46: =C46*'SYS INFO'!$C$9 -> 100.32 | F46: 3225 | G46: 146 | H46: =G46 * 'SYS INFO'!$C$9 -> 96.36
B47: 3300 | C47: 151 | D47: =C47*'SYS INFO'!$C$9 -> 99.66 | F47: 3300 | G47: 147 | H47: =G47 * 'SYS INFO'!$C$9 -> 97.02
B48: 3375 | C48: 149 | D48: =C48*'SYS INFO'!$C$9 -> 98.34 | F48: 3375 | G48: 146 | H48: =G48 * 'SYS INFO'!$C$9 -> 96.36
B49: 3450 | C49: 150 | D49: =C49*'SYS INFO'!$C$9 -> 99 | F49: 3450 | G49: 149 | H49: =G49 * 'SYS INFO'!$C$9 -> 98.34
B50: 3525 | C50: 148 | D50: =C50*'SYS INFO'!$C$9 -> 97.68 | F50: 3525 | G50: 145 | H50: =G50 * 'SYS INFO'!$C$9 -> 95.7
B51: 3600 | C51: 150 | D51: =C51*'SYS INFO'!$C$9 -> 99 | F51: 3600 | G51: 148 | H51: =G51 * 'SYS INFO'!$C$9 -> 97.68
B52: 3675 | C52: 151 | D52: =C52*'SYS INFO'!$C$9 -> 99.66 | F52: 3675 | G52: 147 | H52: =G52 * 'SYS INFO'!$C$9 -> 97.02
B53: 3750 | C53: 151 | D53: =C53*'SYS INFO'!$C$9 -> 99.66 | F53: 3750 | G53: 148 | H53: =G53 * 'SYS INFO'!$C$9 -> 97.68
B54: 3825 | C54: 151 | D54: =C54*'SYS INFO'!$C$9 -> 99.66 | F54: 3825 | G54: 145 | H54: =G54 * 'SYS INFO'!$C$9 -> 95.7
B55: 3900 | C55: 154 | D55: =C55*'SYS INFO'!$C$9 -> 101.64 | F55: 3900 | G55: 149 | H55: =G55 * 'SYS INFO'!$C$9 -> 98.34
... B80: 5775 | C80: 149 | D80: =C80*'SYS INFO'!$C$9 -> 98.34 | F80: 5775 | G80: 149 | H80: =G80 * 'SYS INFO'!$C$9 -> 98.34
B81: 5850 | C81: 157 | D81: =C81*'SYS INFO'!$C$9 -> 103.62 | E81: TRANSFER | F81: 5850 | G81: 151 | H81: =G81 * 'SYS INFO'!$C$9 -> 99.66 | I81: TRANSFER
B82: 5925 | C82: 160 | D82: =C82*'SYS INFO'!$C$9 -> 105.6 | F82: 5925 | G82: 157 | H82: =G82 * 'SYS INFO'!$C$9 -> 103.62
B83: 6000 | C83: 158 | D83: =C83*'SYS INFO'!$C$9 -> 104.28 | F83: 6000 | G83: 156 | H83: =G83 * 'SYS INFO'!$C$9 -> 102.96
B84: 6075 | C84: 160 | D84: =C84*'SYS INFO'!$C$9 -> 105.6 | F84: 6075 | G84: 153 | H84: =G84 * 'SYS INFO'!$C$9 -> 100.98
B85: 6150 | C85: 155 | D85: =C85*'SYS INFO'!$C$9 -> 102.3 | F85: 6150 | G85: 155 | H85: =G85 * 'SYS INFO'!$C$9 -> 102.3
...

Sheet SleepStop
B2: RUN MODE | F2: SLEEP MODE | J2: Power Difference from Run Mode (mW)
B3: Test # | C3: Shunt Voltage (mV) | D3: Estimated System Power (mW) | F3: Test # | G3: Shunt Voltage (mV) | H3: Estimated System Power (mW) | K3: Sleep | L3: STOP0
B4: 1 | C4: 46.95 | D4: =(C4/1000)/('SYS INFO'!$C$3)*'SYS INFO'!$C$4*1000 * 'SYS INFO'!$C$9 -> 96.834375 | F4: 1 | G4: 32.75 | H4: =((G4/1000)/('SYS INFO'!$C$3)*'SYS INFO'!$C$4*1000 - Baselines!$H$10) * 'SYS INFO'!$C$9 -> 60.516106 | J4: CubeMX PCC | K4: =Budget!D7-Budget!D8 -> 33.495 | L4: =Budget!D7-Budget!D9 -> 64.2675
B5: 2 | C5: 46.98 | D5: =(C5/1000)/('SYS INFO'!$C$3)*'SYS INFO'!$C$4*1000 * 'SYS INFO'!$C$9 -> 96.89625 | F5: 2 | G5: 32.36 | H5: =((G5/1000)/('SYS INFO'!$C$3)*'SYS INFO'!$C$4*1000 - Baselines!$H$10) * 'SYS INFO'!$C$9 -> 59.711731 | J5: Measured | K5: =D10-H10 -> 37.007144 | L5: =D10-H22 -> 78.719144
B6: 3 | C6: 47 | D6: =(C6/1000)/('SYS INFO'!$C$3)*'SYS INFO'!$C$4*1000 * 'SYS INFO'!$C$9 -> 96.9375 | F6: 3 | G6: 32.5 | H6: =((G6/1000)/('SYS INFO'!$C$3)*'SYS INFO'!$C$4*1000 - Baselines!$H$10) * 'SYS INFO'!$C$9 -> 60.000481 | J6: Difference | K6: =ABS(K4-K5) -> 3.5121444 | L6: =ABS(L4-L5) -> 14.451644
B7: 4 | C7: 47.15 | D7: =(C7/1000)/('SYS INFO'!$C$3)*'SYS INFO'!$C$4*1000 * 'SYS INFO'!$C$9 -> 97.246875 | F7: 4 | G7: 32.36 | H7: =((G7/1000)/('SYS INFO'!$C$3)*'SYS INFO'!$C$4*1000 - Baselines!$H$10) * 'SYS INFO'!$C$9 -> 59.711731
B8: 5 | C8: 47.1 | D8: =(C8/1000)/('SYS INFO'!$C$3)*'SYS INFO'!$C$4*1000 * 'SYS INFO'!$C$9 -> 97.14375 | F8: 5 | G8: 32.54 | H8: =((G8/1000)/('SYS INFO'!$C$3)*'SYS INFO'!$C$4*1000 - Baselines!$H$10) * 'SYS INFO'!$C$9 -> 60.082981
C10: Average | D10: =AVERAGE(D4:D8) -> 97.01175 | G10: Average | H10: =AVERAGE(H4:H8) -> 60.004606
G12: Minus power from one LED as MCU light indicates SLEEP MODE
F14: STOP0 MODE
F15: Test # | G15: Shunt Voltage (mV) | H15: Estimated System Power (mW)
F16: 1 | G16: 12.3 | H16: =((G16/1000)/('SYS INFO'!$C$3)*'SYS INFO'!$C$4*1000 - Baselines!$H$10) * 'SYS INFO'!$C$9 -> 18.337981
F17: 2 | G17: 12.31 | H17: =((G17/1000)/('SYS INFO'!$C$3)*'SYS INFO'!$C$4*1000 - Baselines!$H$10) * 'SYS INFO'!$C$9 -> 18.358606
F18: 3 | G18: 12.29 | H18: =((G18/1000)/('SYS INFO'!$C$3)*'SYS INFO'!$C$4*1000 - Baselines!$H$10) * 'SYS INFO'!$C$9 -> 18.317356
F19: 4 | G19: 12.26 | H19: =((G19/1000)/('SYS INFO'!$C$3)*'SYS INFO'!$C$4*1000 - Baselines!$H$10) * 'SYS INFO'!$C$9 -> 18.255481
F20: 5 | G20: 12.23 | H20: =((G20/1000)/('SYS INFO'!$C$3)*'SYS INFO'!$C$4*1000 - Baselines!$H$10) * 'SYS INFO'!$C$9 -> 18.193606
G22: Average | H22: =AVERAGE(H16:H20) -> 18.292606
G24: Minus power from one LED as MCU light indicates SLEEP MODE

Sheet Budget
B2: Item | C2: Current (mA) | D2: Power (mW) | E2: Source
B3: CSA | C3: 1 | D3: ='SYS INFO'!$C$5*C3 -> 3.3 | E3: Datasheet
B4: LED | D4: =Baselines!H10 -> 10.652681 | E4: Measurement
B5: HSE | C5: 6 | D5: ='SYS INFO'!$C$5*C5 -> 19.8 | E5: Datasheet
B6: LSE | C6: =0.001 -> 0.001 | D6: ='SYS INFO'!$C$5*C6 -> 0.0033 | E6: Datasheet
B7: MCU (Run) | C7: 19.6 | D7: ='SYS INFO'!$C$5*C7 -> 64.68 | E7: STM32CubeMX PCC | F7: Verified by measurement
B8: MCU (Sleep) | C8: 9.45 | D8: ='SYS INFO'!$C$5*C8 -> 31.185 | E8: STM32CubeMX PCC | F8: Verified by measurement
B9: MCU (Stop0) | C9: =0.125 -> 0.125 | D9: ='SYS INFO'!$C$5*C9 -> 0.4125 | E9: STM32CubeMX PCC | F9: Verified by measurement
B10: QSPI | C10: 15 | D10: ='SYS INFO'!$C$5*C10 -> 49.5 | E10: Datasheet
B11: Camera | D11: ='Camera Test'!W5 -> 52.299254 | E11: Measurement
B12: USB (Data) | D12: ='Camera Test'!W6 -> 61.80251 | E12: Measurement
B13: LDO (Max) | D13: =SUM(D3:D12)*('SYS INFO'!$C$8) -> 151.26664 | E13: Calculation
B14: LDO (Typ.) | D14: =SUM(D3:D7)*('SYS INFO'!$C$8) -> 50.709445 | E14: Calculation
B15: LDO (Low) | D15: =SUM(D3:D6)*('SYS INFO'!$C$8) -> 17.389445 | E15: Calculation
B16: LDO (Lowest) | D16: =(D3+D9)*('SYS INFO'!$C$8) -> 1.9125 | E16: Calculation
C17: Maximum | D17: =SUM(D3:D13)-D8-D9 -> 413.30439
C18: Typical | D18: =SUM(D3:D7)+D14 -> 149.14543
C19: Low | D19: =SUM(D3:D6)+D15+D8 -> 82.330426 | E19: Theoretical, verified by interpolation from Sleep Test
C20: Lowest | D20: =D3+D16+D9 -> 5.625 | E20: Excludes LED, HSE&LSE Disabled. Purely theoretical. Partially verified by STOP0 test
